<?xml version="1.0" encoding="utf-8"?>
<!-- This URDF was automatically created by SolidWorks to URDF Exporter! Originally created by Stephen Brawner (brawner@gmail.com) 
     Commit Version: 1.6.0-4-g7f85cfe  Build Version: 1.6.7995.38578
     For more information, please see http://wiki.ros.org/sw_urdf_exporter -->
<robot
  name="NIXITO 2026.SLDASM">
  <link
    name="base_link">
    <inertial>
      <origin
        xyz="0.00437863011032785 0.00488071387060618 0.110586475666737"
        rpy="0 0 0" />
      <mass
        value="25.5662855279903" />
      <inertia
        ixx="0.0870860204401099"
        ixy="4.66820104436843E-05"
        ixz="-0.00156328344981155"
        iyy="0.277462313947464"
        iyz="-6.55386356774102E-05"
        izz="0.287111653197617" />
    </inertial>
    <visual>
      <origin
        xyz="0 0 0"
        rpy="0 0 0" />
      <geometry>
        <mesh
          filename="package://nixito_description/meshes/base_link.STL" />
      </geometry>
      <material
        name="">
        <color
          rgba="0.0823529411764706 0.0823529411764706 0.0823529411764706 1" />
      </material>
    </visual>
    <collision>
      <origin
        xyz="0 0 0"
        rpy="0 0 0" />
      <geometry>
        <mesh
          filename="package://nixito_description/meshes/base_link.STL" />
      </geometry>
    </collision>
  </link>
  <link
    name="dir_R_link">
    <inertial>
      <origin
        xyz="-5.64265449815027E-06 1.63708517160466E-06 -0.0384132623661952"
        rpy="0 0 0" />
      <mass
        value="1.3754826889591" />
      <inertia
        ixx="0.00316961288572545"
        ixy="-1.56630451990999E-08"
        ixz="-7.12322524380198E-07"
        iyy="0.00316956344234396"
        iyz="2.06663820586351E-07"
        izz="0.00491633292421438" />
    </inertial>
    <visual>
      <origin
        xyz="0 0 0"
        rpy="0 0 0" />
      <geometry>
        <mesh
          filename="package://nixito_description/meshes/dir_R_link.STL" />
      </geometry>
      <material
        name="">
        <color
          rgba="0.792156862745098 0.819607843137255 0.933333333333333 1" />
      </material>
    </visual>
    <collision>
      <origin
        xyz="0 0 0"
        rpy="0 0 0" />
      <geometry>
        <mesh
          filename="package://nixito_description/meshes/dir_R_link.STL" />
      </geometry>
    </collision>
  </link>
  <joint
    name="dir_R_joint"
    type="continuous">
    <origin
      xyz="-0.29371 -0.22792 0.075"
      rpy="1.5708 0 0" />
    <parent
      link="base_link" />
    <child
      link="dir_R_link" />
    <axis
      xyz="0 0 1" />
    <limit
      effort="100"
      velocity="100" />
    <dynamics
      friction="0.1" />
  </joint>
  <link
    name="dir_L_link">
    <inertial>
      <origin
        xyz="-4.99717648289044E-06 3.08995548813085E-06 -0.0364132623661902"
        rpy="0 0 0" />
      <mass
        value="1.3754826889591" />
      <inertia
        ixx="0.00316960124072055"
        ixy="-2.61819263191363E-08"
        ixz="-6.30838089164463E-07"
        iyy="0.00316957508734887"
        iyz="3.90072581269323E-07"
        izz="0.00491633292421439" />
    </inertial>
    <visual>
      <origin
        xyz="0 0 0"
        rpy="0 0 0" />
      <geometry>
        <mesh
          filename="package://nixito_description/meshes/dir_L_link.STL" />
      </geometry>
      <material
        name="">
        <color
          rgba="0.792156862745098 0.819607843137255 0.933333333333333 1" />
      </material>
    </visual>
    <collision>
      <origin
        xyz="0 0 0"
        rpy="0 0 0" />
      <geometry>
        <mesh
          filename="package://nixito_description/meshes/dir_L_link.STL" />
      </geometry>
    </collision>
  </link>
  <joint
    name="dir_L_joint"
    type="continuous">
    <origin
      xyz="-0.29371 0.22608 0.075"
      rpy="1.5708 0 3.1416" />
    <parent
      link="base_link" />
    <child
      link="dir_L_link" />
    <axis
      xyz="0 0 1" />
    <limit
      effort="100"
      velocity="100" />
    <dynamics
      friction="0.1" />
  </joint>
  <link
    name="flipper_R_link">
    <inertial>
      <origin
        xyz="0.10014361960493 1.01555862551256E-05 -0.00488199703848846"
        rpy="0 0 0" />
      <mass
        value="0.875836999292697" />
      <inertia
        ixx="0.000962299324912456"
        ixy="-2.50556230470828E-09"
        ixz="-7.65665235947313E-06"
        iyy="0.00851689142758344"
        iyz="8.58020499110178E-07"
        izz="0.0085709150591796" />
    </inertial>
    <visual>
      <origin
        xyz="0 0 0"
        rpy="0 0 0" />
      <geometry>
        <mesh
          filename="package://nixito_description/meshes/flipper_R_link.STL" />
      </geometry>
      <material
        name="">
        <color
          rgba="0.792156862745098 0.819607843137255 0.933333333333333 1" />
      </material>
    </visual>
    <collision>
      <origin
        xyz="0 0 0"
        rpy="0 0 0" />
      <geometry>
        <mesh
          filename="package://nixito_description/meshes/flipper_R_link.STL" />
      </geometry>
    </collision>
  </link>
  <joint
    name="flipper_R_joint"
    type="fixed">
    <origin
      xyz="0.26929 -0.26547 0.075"
      rpy="-1.5708 -0.050021 3.1416" />
    <parent
      link="base_link" />
    <child
      link="flipper_R_link" />
    <axis
      xyz="0 0 1" />
    <limit
      effort="100"
      velocity="100" />
    <dynamics
      friction="0.1" />
  </joint>
  <link
    name="flipper_L_link">
    <inertial>
      <origin
        xyz="0.00238935305921779 -0.100126505199991 0.240800885856043"
        rpy="0 0 0" />
      <mass
        value="0.875836999292697" />
      <inertia
        ixx="0.00851256923866617"
        ixy="0.000180193083284295"
        ixz="1.8031713726932E-07"
        iyy="0.000966621513829713"
        iyz="-8.41930116924885E-06"
        izz="0.00857091505917959" />
    </inertial>
    <visual>
      <origin
        xyz="0 0 0"
        rpy="0 0 0" />
      <geometry>
        <mesh
          filename="package://nixito_description/meshes/flipper_L_link.STL" />
      </geometry>
      <material
        name="">
        <color
          rgba="0.792156862745098 0.819607843137255 0.933333333333333 1" />
      </material>
    </visual>
    <collision>
      <origin
        xyz="0 0 0"
        rpy="0 0 0" />
      <geometry>
        <mesh
          filename="package://nixito_description/meshes/flipper_L_link.STL" />
      </geometry>
    </collision>
  </link>
  <joint
    name="flipper_L_joint"
    type="fixed">
    <origin
      xyz="0.26929 0.020085 0.075"
      rpy="-1.5708 -1.5446 0" />
    <parent
      link="base_link" />
    <child
      link="flipper_L_link" />
    <axis
      xyz="0 0 1" />
    <limit
      effort="100"
      velocity="100" />
    <dynamics
      friction="0.1" />
  </joint>
  <link
    name="Hombro_link">
    <inertial>
      <origin
        xyz="0.000329220499828003 0.00386263654781993 0.0272367282663454"
        rpy="0 0 0" />
      <mass
        value="0.101386819832072" />
      <inertia
        ixx="0.000131260455190187"
        ixy="1.14653159950188E-06"
        ixz="-5.19436298812016E-07"
        iyy="0.00011295516987088"
        iyz="-1.36136929698582E-05"
        izz="9.02372535296635E-05" />
    </inertial>
    <visual>
      <origin
        xyz="0 0 0"
        rpy="0 0 0" />
      <geometry>
        <mesh
          filename="package://nixito_description/meshes/Hombro_link.STL" />
      </geometry>
      <material
        name="">
        <color
          rgba="0.909803921568627 0.443137254901961 0.0313725490196078 1" />
      </material>
    </visual>
    <collision>
      <origin
        xyz="0 0 0"
        rpy="0 0 0" />
      <geometry>
        <mesh
          filename="package://nixito_description/meshes/Hombro_link.STL" />
      </geometry>
    </collision>
  </link>
  <joint
    name="Hombro_joint"
    type="continuous">
    <origin
      xyz="0.25649 -0.070909 0.24936"
      rpy="0 0 0" />
    <parent
      link="base_link" />
    <child
      link="Hombro_link" />
    <axis
      xyz="0 0 1" />
    <limit
      lower="0"
      upper="0"
      effort="100"
      velocity="100" />
    <dynamics
      friction="0.1" />
  </joint>
  <link
    name="E1_link">
    <inertial>
      <origin
        xyz="-5.97803541966951E-05 0.0840247601562089 0.0130180348999693"
        rpy="0 0 0" />
      <mass
        value="0.192290389959318" />
      <inertia
        ixx="0.000566355912897058"
        ixy="-2.9126267212515E-09"
        ixz="5.11953924486943E-10"
        iyy="7.61514048875042E-05"
        iyz="-1.41627060807744E-06"
        izz="0.000596781058948479" />
    </inertial>
    <visual>
      <origin
        xyz="0 0 0"
        rpy="0 0 0" />
      <geometry>
        <mesh
          filename="package://nixito_description/meshes/E1_link.STL" />
      </geometry>
      <material
        name="">
        <color
          rgba="0.792156862745098 0.819607843137255 0.933333333333333 1" />
      </material>
    </visual>
    <collision>
      <origin
        xyz="0 0 0"
        rpy="0 0 0" />
      <geometry>
        <mesh
          filename="package://nixito_description/meshes/E1_link.STL" />
      </geometry>
    </collision>
  </link>
  <joint
    name="E1_joint"
    type="continuous">
    <origin
      xyz="0 0.039994 0.043491"
      rpy="1.5708 0 3.1416" />
    <parent
      link="Hombro_link" />
    <child
      link="E1_link" />
    <axis
      xyz="0 0 1" />
    <limit
      effort="100"
      velocity="100" />
    <dynamics
      friction="0.1" />
  </joint>
  <link
    name="E2_link">
    <inertial>
      <origin
        xyz="1.29229049467133E-05 0.0803343269372555 0.00131136435295082"
        rpy="0 0 0" />
      <mass
        value="0.135201035415251" />
      <inertia
        ixx="0.000316772469867071"
        ixy="-1.15600964123082E-07"
        ixz="7.67028277549168E-09"
        iyy="5.41327489366859E-05"
        iyz="-1.27830667660268E-06"
        izz="0.000340633230607744" />
    </inertial>
    <visual>
      <origin
        xyz="0 0 0"
        rpy="0 0 0" />
      <geometry>
        <mesh
          filename="package://nixito_description/meshes/E2_link.STL" />
      </geometry>
      <material
        name="">
        <color
          rgba="0.909803921568627 0.443137254901961 0.0313725490196078 1" />
      </material>
    </visual>
    <collision>
      <origin
        xyz="0 0 0"
        rpy="0 0 0" />
      <geometry>
        <mesh
          filename="package://nixito_description/meshes/E2_link.STL" />
      </geometry>
    </collision>
  </link>
  <joint
    name="E2_joint"
    type="continuous">
    <origin
      xyz="0 0.15071 -0.023865"
      rpy="3.1416 0 3.1416" />
    <parent
      link="E1_link" />
    <child
      link="E2_link" />
    <axis
      xyz="0 0 1" />
    <limit
      effort="100"
      velocity="100" />
    <dynamics
      friction="0.1" />
  </joint>
  <link
    name="E3_link">
    <inertial>
      <origin
        xyz="0.0390723877633097 0.00588082672902912 0.0105723183138784"
        rpy="0 0 0" />
      <mass
        value="0.0998628576612143" />
      <inertia
        ixx="4.80345624492912E-05"
        ixy="-1.06378505581651E-05"
        ixz="1.41195084359271E-06"
        iyy="7.76267111046649E-05"
        iyz="3.82828489061288E-07"
        izz="9.11815154704042E-05" />
    </inertial>
    <visual>
      <origin
        xyz="0 0 0"
        rpy="0 0 0" />
      <geometry>
        <mesh
          filename="package://nixito_description/meshes/E3_link.STL" />
      </geometry>
      <material
        name="">
        <color
          rgba="0.792156862745098 0.819607843137255 0.933333333333333 1" />
      </material>
    </visual>
    <collision>
      <origin
        xyz="0 0 0"
        rpy="0 0 0" />
      <geometry>
        <mesh
          filename="package://nixito_description/meshes/E3_link.STL" />
      </geometry>
    </collision>
  </link>
  <joint
    name="E3_joint"
    type="continuous">
    <origin
      xyz="0 0.13629 -0.023865"
      rpy="-3.1416 0 1.5708" />
    <parent
      link="E2_link" />
    <child
      link="E3_link" />
    <axis
      xyz="0 0 1" />
    <limit
      effort="100"
      velocity="100" />
    <dynamics
      friction="0.1" />
  </joint>
  <link
    name="gripper_link">
    <inertial>
      <origin
        xyz="-0.00049595 -0.0036162 -0.0030286"
        rpy="0 0 0" />
      <mass
        value="0.053209" />
      <inertia
        ixx="1.1716E-05"
        ixy="-1.1243E-08"
        ixz="-7.084E-08"
        iyy="1.9136E-05"
        iyz="9.1596E-07"
        izz="9.5435E-06" />
    </inertial>
    <visual>
      <origin
        xyz="0 0 0"
        rpy="0 0 0" />
      <geometry>
        <mesh
          filename="package://nixito_description/meshes/gripper_link.STL" />
      </geometry>
      <material
        name="">
        <color
          rgba="0.78039 0.76078 0.74118 1" />
      </material>
    </visual>
    <collision>
      <origin
        xyz="0 0 0"
        rpy="0 0 0" />
      <geometry>
        <mesh
          filename="package://nixito_description/meshes/gripper_link.STL" />
      </geometry>
    </collision>
  </link>
  <joint
    name="gripper_joint"
    type="fixed">
    <origin
      xyz="0.13835 0.0045 0.01815"
      rpy="3.1416 1.5708 0" />
    <parent
      link="E3_link" />
    <child
      link="gripper_link" />
    <axis
      xyz="0 0 1" />
    <limit
      effort="100"
      velocity="100" />
    <dynamics
      friction="0.1" />
  </joint>
</robot>